5:return {{["y"] = 0, ["x"] = 0, ["name"] = "default:wood", ["z"] = 0, ["meta"] = {["inventory"] = {}, ["fields"] = {}}}, {["y"] = 0, ["x"] = 0, ["name"] = "default:wood", ["z"] = 1, ["meta"] = {["inventory"] = {}, ["fields"] = {}}}, {["y"] = 0, ["x"] = 0, ["name"] = "stairs:stair_wood", ["z"] = 2, ["meta"] = {["inventory"] = {}, ["fields"] = {}}, ["param2"] = 1, ["param1"] = 94}, {["y"] = 0, ["x"] = 0, ["name"] = "default:wood", ["z"] = 3, ["meta"] = {["inventory"] = {}, ["fields"] = {}}}, {["y"] = 0, ["x"] = 0, ["name"] = "default:wood", ["z"] = 4, ["meta"] = {["inventory"] = {}, ["fields"] = {}}}, {["y"] = 1, ["x"] = 0, ["name"] = "default:fence_wood", ["z"] = 0, ["meta"] = {["inventory"] = {}, ["fields"] = {}}, ["param1"] = 78}, {["y"] = 1, ["x"] = 0, ["name"] = "default:fence_wood", ["z"] = 1, ["meta"] = {["inventory"] = {}, ["fields"] = {}}, ["param1"] = 94}, {["y"] = 1, ["x"] = 0, ["name"] = "default:fence_wood", ["z"] = 3, ["meta"] = {["inventory"] = {}, ["fields"] = {}}, ["param1"] = 94}, {["y"] = 1, ["x"] = 0, ["name"] = "default:fence_wood", ["z"] = 4, ["meta"] = {["inventory"] = {}, ["fields"] = {}}, ["param1"] = 78}, {["y"] = 2, ["x"] = 0, ["name"] = "default:fence_wood", ["z"] = 0, ["meta"] = {["inventory"] = {}, ["fields"] = {}}, ["param1"] = 94}, {["y"] = 2, ["x"] = 0, ["name"] = "default:fence_wood", ["z"] = 4, ["meta"] = {["inventory"] = {}, ["fields"] = {}}, ["param1"] = 94}, {["y"] = 3, ["x"] = 0, ["name"] = "default:fence_wood", ["z"] = 0, ["meta"] = {["inventory"] = {}, ["fields"] = {}}, ["param1"] = 78}, {["y"] = 3, ["x"] = 0, ["name"] = "default:fence_wood", ["z"] = 4, ["meta"] = {["inventory"] = {}, ["fields"] = {}}, ["param1"] = 78}, {["y"] = 4, ["x"] = 0, ["name"] = "stairs:slab_junglewood", ["z"] = 0, ["meta"] = {["inventory"] = {}, ["fields"] = {}}, ["param1"] = 94}, {["y"] = 4, ["x"] = 0, ["name"] = "stairs:slab_junglewood", ["z"] = 1, ["meta"] = {["inventory"] = {}, ["fields"] = {}}, ["param1"] = 110}, {["y"] = 4, ["x"] = 0, ["name"] = "stairs:slab_junglewood", ["z"] = 2, ["meta"] = {["inventory"] = {}, ["fields"] = {}}, ["param1"] = 94}, {["y"] = 4, ["x"] = 0, ["name"] = "stairs:slab_junglewood", ["z"] = 3, ["meta"] = {["inventory"] = {}, ["fields"] = {}}, ["param1"] = 78}, {["y"] = 4, ["x"] = 0, ["name"] = "stairs:slab_junglewood", ["z"] = 4, ["meta"] = {["inventory"] = {}, ["fields"] = {}}, ["param1"] = 62}, {["y"] = 0, ["x"] = 1, ["name"] = "stairs:stair_wood", ["z"] = 0, ["meta"] = {["inventory"] = {}, ["fields"] = {}}, ["param1"] = 78}, {["y"] = 0, ["x"] = 1, ["name"] = "default:wood", ["z"] = 1, ["meta"] = {["inventory"] = {}, ["fields"] = {}}}, {["y"] = 0, ["x"] = 1, ["name"] = "default:wood", ["z"] = 2, ["meta"] = {["inventory"] = {}, ["fields"] = {}}}, {["y"] = 0, ["x"] = 1, ["name"] = "default:wood", ["z"] = 3, ["meta"] = {["inventory"] = {}, ["fields"] = {}}}, {["y"] = 0, ["x"] = 1, ["name"] = "stairs:stair_wood", ["z"] = 4, ["meta"] = {["inventory"] = {}, ["fields"] = {}}, ["param2"] = 2, ["param1"] = 78}, {["y"] = 4, ["x"] = 1, ["name"] = "stairs:slab_junglewood", ["z"] = 0, ["meta"] = {["inventory"] = {}, ["fields"] = {}}, ["param1"] = 110}, {["y"] = 4, ["x"] = 1, ["name"] = "stairs:slab_junglewood", ["z"] = 1, ["meta"] = {["inventory"] = {}, ["fields"] = {}}, ["param1"] = 126}, {["y"] = 4, ["x"] = 1, ["name"] = "stairs:slab_junglewood", ["z"] = 2, ["meta"] = {["inventory"] = {}, ["fields"] = {}}, ["param1"] = 110}, {["y"] = 4, ["x"] = 1, ["name"] = "stairs:slab_junglewood", ["z"] = 3, ["meta"] = {["inventory"] = {}, ["fields"] = {}}, ["param1"] = 94}, {["y"] = 4, ["x"] = 1, ["name"] = "stairs:slab_junglewood", ["z"] = 4, ["meta"] = {["inventory"] = {}, ["fields"] = {}}, ["param1"] = 78}, {["y"] = 0, ["x"] = 2, ["name"] = "default:tree", ["z"] = 0, ["meta"] = {["inventory"] = {}, ["fields"] = {}}}, {["y"] = 0, ["x"] = 2, ["name"] = "default:wood", ["z"] = 1, ["meta"] = {["inventory"] = {}, ["fields"] = {}}}, {["y"] = 0, ["x"] = 2, ["name"] = "default:wood", ["z"] = 2, ["meta"] = {["inventory"] = {}, ["fields"] = {}}}, {["y"] = 0, ["x"] = 2, ["name"] = "default:wood", ["z"] = 3, ["meta"] = {["inventory"] = {}, ["fields"] = {}}}, {["y"] = 0, ["x"] = 2, ["name"] = "default:tree", ["z"] = 4, ["meta"] = {["inventory"] = {}, ["fields"] = {}}}, {["y"] = 1, ["x"] = 2, ["name"] = "default:tree", ["z"] = 0, ["meta"] = {["inventory"] = {}, ["fields"] = {}}}, {["y"] = 1, ["x"] = 2, ["name"] = "default:wood", ["z"] = 1, ["meta"] = {["inventory"] = {}, ["fields"] = {}}}, {["y"] = 1, ["x"] = 2, ["name"] = "doors:door_wood_a", ["z"] = 2, ["meta"] = {["inventory"] = {}, ["fields"] = {["state"] = "0"}}, ["param2"] = 1, ["param1"] = 140}, {["y"] = 1, ["x"] = 2, ["name"] = "default:wood", ["z"] = 3, ["meta"] = {["inventory"] = {}, ["fields"] = {}}}, {["y"] = 1, ["x"] = 2, ["name"] = "default:tree", ["z"] = 4, ["meta"] = {["inventory"] = {}, ["fields"] = {}}}, {["y"] = 2, ["x"] = 2, ["name"] = "default:tree", ["z"] = 0, ["meta"] = {["inventory"] = {}, ["fields"] = {}}}, {["y"] = 2, ["x"] = 2, ["name"] = "default:wood", ["z"] = 1, ["meta"] = {["inventory"] = {}, ["fields"] = {}}}, {["y"] = 2, ["x"] = 2, ["name"] = "doors:hidden", ["z"] = 2, ["meta"] = {["inventory"] = {}, ["fields"] = {}}, ["param2"] = 1, ["param1"] = 156}, {["y"] = 2, ["x"] = 2, ["name"] = "default:wood", ["z"] = 3, ["meta"] = {["inventory"] = {}, ["fields"] = {}}}, {["y"] = 2, ["x"] = 2, ["name"] = "default:tree", ["z"] = 4, ["meta"] = {["inventory"] = {}, ["fields"] = {}}}, {["y"] = 3, ["x"] = 2, ["name"] = "default:tree", ["z"] = 0, ["meta"] = {["inventory"] = {}, ["fields"] = {}}}, {["y"] = 3, ["x"] = 2, ["name"] = "default:wood", ["z"] = 1, ["meta"] = {["inventory"] = {}, ["fields"] = {}}}, {["y"] = 3, ["x"] = 2, ["name"] = "default:wood", ["z"] = 2, ["meta"] = {["inventory"] = {}, ["fields"] = {}}}, {["y"] = 3, ["x"] = 2, ["name"] = "default:wood", ["z"] = 3, ["meta"] = {["inventory"] = {}, ["fields"] = {}}}, {["y"] = 3, ["x"] = 2, ["name"] = "default:tree", ["z"] = 4, ["meta"] = {["inventory"] = {}, ["fields"] = {}}}, {["y"] = 4, ["x"] = 2, ["name"] = "stairs:slab_junglewood", ["z"] = 0, ["meta"] = {["inventory"] = {}, ["fields"] = {}}, ["param1"] = 126}, {["y"] = 4, ["x"] = 2, ["name"] = "stairs:slab_junglewood", ["z"] = 1, ["meta"] = {["inventory"] = {}, ["fields"] = {}}, ["param1"] = 142}, {["y"] = 4, ["x"] = 2, ["name"] = "stairs:slab_junglewood", ["z"] = 2, ["meta"] = {["inventory"] = {}, ["fields"] = {}}, ["param1"] = 126}, {["y"] = 4, ["x"] = 2, ["name"] = "stairs:slab_junglewood", ["z"] = 3, ["meta"] = {["inventory"] = {}, ["fields"] = {}}, ["param1"] = 110}, {["y"] = 4, ["x"] = 2, ["name"] = "stairs:slab_junglewood", ["z"] = 4, ["meta"] = {["inventory"] = {}, ["fields"] = {}}, ["param1"] = 94}, {["y"] = 0, ["x"] = 3, ["name"] = "default:wood", ["z"] = 0, ["meta"] = {["inventory"] = {}, ["fields"] = {}}}, {["y"] = 0, ["x"] = 3, ["name"] = "default:wood", ["z"] = 1, ["meta"] = {["inventory"] = {}, ["fields"] = {}}}, {["y"] = 0, ["x"] = 3, ["name"] = "default:wood", ["z"] = 2, ["meta"] = {["inventory"] = {}, ["fields"] = {}}}, {["y"] = 0, ["x"] = 3, ["name"] = "default:wood", ["z"] = 3, ["meta"] = {["inventory"] = {}, ["fields"] = {}}}, {["y"] = 0, ["x"] = 3, ["name"] = "default:wood", ["z"] = 4, ["meta"] = {["inventory"] = {}, ["fields"] = {}}}, {["y"] = 1, ["x"] = 3, ["name"] = "default:wood", ["z"] = 0, ["meta"] = {["inventory"] = {}, ["fields"] = {}}}, {["y"] = 1, ["x"] = 3, ["name"] = "default:furnace", ["z"] = 1, ["meta"] = {["inventory"] = {["dst"] = {"", "", "", ""}, ["src"] = {""}, ["fuel"] = {""}}, ["fields"] = {["formspec"] = "size[8,8.5]list[context;src;2.75,0.5;1,1;]list[context;fuel;2.75,2.5;1,1;]image[2.75,1.5;1,1;default_furnace_fire_bg.png]image[3.75,1.5;1,1;gui_furnace_arrow_bg.png^[transformR270]list[context;dst;4.75,0.96;2,2;]list[current_player;main;0,4.25;8,1;]list[current_player;main;0,5.5;8,3;8]listring[context;dst]listring[current_player;main]listring[context;src]listring[current_player;main]listring[context;fuel]listring[current_player;main]image[0,4.25;1,1;gui_hb_bg.png]image[1,4.25;1,1;gui_hb_bg.png]image[2,4.25;1,1;gui_hb_bg.png]image[3,4.25;1,1;gui_hb_bg.png]image[4,4.25;1,1;gui_hb_bg.png]image[5,4.25;1,1;gui_hb_bg.png]image[6,4.25;1,1;gui_hb_bg.png]image[7,4.25;1,1;gui_hb_bg.png]"}}, ["param2"] = 3}, {["y"] = 1, ["x"] = 3, ["name"] = "wool:red", ["z"] = 3, ["meta"] = {["inventory"] = {}, ["fields"] = {}}}, {["y"] = 1, ["x"] = 3, ["name"] = "default:wood", ["z"] = 4, ["meta"] = {["inventory"] = {}, ["fields"] = {}}}, {["y"] = 2, ["x"] = 3, ["name"] = "default:wood", ["z"] = 0, ["meta"] = {["inventory"] = {}, ["fields"] = {}}}, {["y"] = 2, ["x"] = 3, ["name"] = "default:wood", ["z"] = 4, ["meta"] = {["inventory"] = {}, ["fields"] = {}}}, {["y"] = 3, ["x"] = 3, ["name"] = "default:wood", ["z"] = 0, ["meta"] = {["inventory"] = {}, ["fields"] = {}}}, {["y"] = 3, ["x"] = 3, ["name"] = "default:wood", ["z"] = 4, ["meta"] = {["inventory"] = {}, ["fields"] = {}}}, {["y"] = 4, ["x"] = 3, ["name"] = "stairs:slab_junglewood", ["z"] = 0, ["meta"] = {["inventory"] = {}, ["fields"] = {}}, ["param1"] = 142}, {["y"] = 4, ["x"] = 3, ["name"] = "stairs:slab_junglewood", ["z"] = 1, ["meta"] = {["inventory"] = {}, ["fields"] = {}}, ["param1"] = 158}, {["y"] = 4, ["x"] = 3, ["name"] = "stairs:slab_junglewood", ["z"] = 2, ["meta"] = {["inventory"] = {}, ["fields"] = {}}, ["param1"] = 142}, {["y"] = 4, ["x"] = 3, ["name"] = "stairs:slab_junglewood", ["z"] = 3, ["meta"] = {["inventory"] = {}, ["fields"] = {}}, ["param1"] = 126}, {["y"] = 4, ["x"] = 3, ["name"] = "stairs:slab_junglewood", ["z"] = 4, ["meta"] = {["inventory"] = {}, ["fields"] = {}}, ["param1"] = 110}, {["y"] = 0, ["x"] = 4, ["name"] = "default:wood", ["z"] = 0, ["meta"] = {["inventory"] = {}, ["fields"] = {}}}, {["y"] = 0, ["x"] = 4, ["name"] = "default:wood", ["z"] = 1, ["meta"] = {["inventory"] = {}, ["fields"] = {}}}, {["y"] = 0, ["x"] = 4, ["name"] = "default:wood", ["z"] = 2, ["meta"] = {["inventory"] = {}, ["fields"] = {}}}, {["y"] = 0, ["x"] = 4, ["name"] = "default:wood", ["z"] = 3, ["meta"] = {["inventory"] = {}, ["fields"] = {}}}, {["y"] = 0, ["x"] = 4, ["name"] = "default:wood", ["z"] = 4, ["meta"] = {["inventory"] = {}, ["fields"] = {}}}, {["y"] = 1, ["x"] = 4, ["name"] = "default:wood", ["z"] = 0, ["meta"] = {["inventory"] = {}, ["fields"] = {}}}, {["y"] = 1, ["x"] = 4, ["name"] = "wool:red", ["z"] = 3, ["meta"] = {["inventory"] = {}, ["fields"] = {}}}, {["y"] = 1, ["x"] = 4, ["name"] = "default:wood", ["z"] = 4, ["meta"] = {["inventory"] = {}, ["fields"] = {}}}, {["y"] = 2, ["x"] = 4, ["name"] = "default:wood", ["z"] = 0, ["meta"] = {["inventory"] = {}, ["fields"] = {}}}, {["y"] = 2, ["x"] = 4, ["name"] = "default:torch_wall", ["z"] = 1, ["meta"] = {["inventory"] = {}, ["fields"] = {}}, ["param2"] = 5, ["param1"] = 204}, {["y"] = 2, ["x"] = 4, ["name"] = "default:wood", ["z"] = 4, ["meta"] = {["inventory"] = {}, ["fields"] = {}}}, {["y"] = 3, ["x"] = 4, ["name"] = "default:wood", ["z"] = 0, ["meta"] = {["inventory"] = {}, ["fields"] = {}}}, {["y"] = 3, ["x"] = 4, ["name"] = "default:wood", ["z"] = 4, ["meta"] = {["inventory"] = {}, ["fields"] = {}}}, {["y"] = 4, ["x"] = 4, ["name"] = "stairs:slab_junglewood", ["z"] = 0, ["meta"] = {["inventory"] = {}, ["fields"] = {}}, ["param1"] = 158}, {["y"] = 4, ["x"] = 4, ["name"] = "stairs:slab_junglewood", ["z"] = 1, ["meta"] = {["inventory"] = {}, ["fields"] = {}}, ["param1"] = 174}, {["y"] = 4, ["x"] = 4, ["name"] = "stairs:slab_junglewood", ["z"] = 2, ["meta"] = {["inventory"] = {}, ["fields"] = {}}, ["param1"] = 158}, {["y"] = 4, ["x"] = 4, ["name"] = "stairs:slab_junglewood", ["z"] = 3, ["meta"] = {["inventory"] = {}, ["fields"] = {}}, ["param1"] = 142}, {["y"] = 4, ["x"] = 4, ["name"] = "stairs:slab_junglewood", ["z"] = 4, ["meta"] = {["inventory"] = {}, ["fields"] = {}}, ["param1"] = 126}, {["y"] = 0, ["x"] = 5, ["name"] = "default:wood", ["z"] = 0, ["meta"] = {["inventory"] = {}, ["fields"] = {}}}, {["y"] = 0, ["x"] = 5, ["name"] = "default:wood", ["z"] = 1, ["meta"] = {["inventory"] = {}, ["fields"] = {}}}, {["y"] = 0, ["x"] = 5, ["name"] = "default:wood", ["z"] = 2, ["meta"] = {["inventory"] = {}, ["fields"] = {}}}, {["y"] = 0, ["x"] = 5, ["name"] = "default:wood", ["z"] = 3, ["meta"] = {["inventory"] = {}, ["fields"] = {}}}, {["y"] = 0, ["x"] = 5, ["name"] = "default:wood", ["z"] = 4, ["meta"] = {["inventory"] = {}, ["fields"] = {}}}, {["y"] = 1, ["x"] = 5, ["name"] = "default:wood", ["z"] = 0, ["meta"] = {["inventory"] = {}, ["fields"] = {}}}, {["y"] = 1, ["x"] = 5, ["name"] = "default:chest", ["z"] = 1, ["meta"] = {["inventory"] = {["main"] = {"", "", "", "", "", "", "", "", "", "", "", "", "", "", "", "", "", "", "", "", "", "", "", "", "", "", "", "", "", "", "", ""}}, ["fields"] = {["infotext"] = "Chest"}}, ["param2"] = 2, ["param1"] = 171}, {["y"] = 1, ["x"] = 5, ["name"] = "wool:white", ["z"] = 3, ["meta"] = {["inventory"] = {}, ["fields"] = {}}}, {["y"] = 1, ["x"] = 5, ["name"] = "default:wood", ["z"] = 4, ["meta"] = {["inventory"] = {}, ["fields"] = {}}}, {["y"] = 2, ["x"] = 5, ["name"] = "default:wood", ["z"] = 0, ["meta"] = {["inventory"] = {}, ["fields"] = {}}}, {["y"] = 2, ["x"] = 5, ["name"] = "default:apple", ["z"] = 1, ["meta"] = {["inventory"] = {}, ["fields"] = {}}, ["param2"] = 1, ["param1"] = 188}, {["y"] = 2, ["x"] = 5, ["name"] = "default:wood", ["z"] = 4, ["meta"] = {["inventory"] = {}, ["fields"] = {}}}, {["y"] = 3, ["x"] = 5, ["name"] = "default:wood", ["z"] = 0, ["meta"] = {["inventory"] = {}, ["fields"] = {}}}, {["y"] = 3, ["x"] = 5, ["name"] = "default:wood", ["z"] = 4, ["meta"] = {["inventory"] = {}, ["fields"] = {}}}, {["y"] = 4, ["x"] = 5, ["name"] = "stairs:slab_junglewood", ["z"] = 0, ["meta"] = {["inventory"] = {}, ["fields"] = {}}, ["param1"] = 142}, {["y"] = 4, ["x"] = 5, ["name"] = "stairs:slab_junglewood", ["z"] = 1, ["meta"] = {["inventory"] = {}, ["fields"] = {}}, ["param1"] = 158}, {["y"] = 4, ["x"] = 5, ["name"] = "stairs:slab_junglewood", ["z"] = 2, ["meta"] = {["inventory"] = {}, ["fields"] = {}}, ["param1"] = 142}, {["y"] = 4, ["x"] = 5, ["name"] = "stairs:slab_junglewood", ["z"] = 3, ["meta"] = {["inventory"] = {}, ["fields"] = {}}, ["param1"] = 126}, {["y"] = 4, ["x"] = 5, ["name"] = "stairs:slab_junglewood", ["z"] = 4, ["meta"] = {["inventory"] = {}, ["fields"] = {}}, ["param1"] = 110}, {["y"] = 0, ["x"] = 6, ["name"] = "default:tree", ["z"] = 0, ["meta"] = {["inventory"] = {}, ["fields"] = {}}}, {["y"] = 0, ["x"] = 6, ["name"] = "default:wood", ["z"] = 1, ["meta"] = {["inventory"] = {}, ["fields"] = {}}}, {["y"] = 0, ["x"] = 6, ["name"] = "default:wood", ["z"] = 2, ["meta"] = {["inventory"] = {}, ["fields"] = {}}}, {["y"] = 0, ["x"] = 6, ["name"] = "default:wood", ["z"] = 3, ["meta"] = {["inventory"] = {}, ["fields"] = {}}}, {["y"] = 0, ["x"] = 6, ["name"] = "default:tree", ["z"] = 4, ["meta"] = {["inventory"] = {}, ["fields"] = {}}}, {["y"] = 1, ["x"] = 6, ["name"] = "default:tree", ["z"] = 0, ["meta"] = {["inventory"] = {}, ["fields"] = {}}}, {["y"] = 1, ["x"] = 6, ["name"] = "default:wood", ["z"] = 1, ["meta"] = {["inventory"] = {}, ["fields"] = {}}}, {["y"] = 1, ["x"] = 6, ["name"] = "default:wood", ["z"] = 2, ["meta"] = {["inventory"] = {}, ["fields"] = {}}}, {["y"] = 1, ["x"] = 6, ["name"] = "default:wood", ["z"] = 3, ["meta"] = {["inventory"] = {}, ["fields"] = {}}}, {["y"] = 1, ["x"] = 6, ["name"] = "default:tree", ["z"] = 4, ["meta"] = {["inventory"] = {}, ["fields"] = {}}}, {["y"] = 2, ["x"] = 6, ["name"] = "default:tree", ["z"] = 0, ["meta"] = {["inventory"] = {}, ["fields"] = {}}}, {["y"] = 2, ["x"] = 6, ["name"] = "default:wood", ["z"] = 1, ["meta"] = {["inventory"] = {}, ["fields"] = {}}}, {["y"] = 2, ["x"] = 6, ["name"] = "default:wood", ["z"] = 2, ["meta"] = {["inventory"] = {}, ["fields"] = {}}}, {["y"] = 2, ["x"] = 6, ["name"] = "default:wood", ["z"] = 3, ["meta"] = {["inventory"] = {}, ["fields"] = {}}}, {["y"] = 2, ["x"] = 6, ["name"] = "default:tree", ["z"] = 4, ["meta"] = {["inventory"] = {}, ["fields"] = {}}}, {["y"] = 3, ["x"] = 6, ["name"] = "default:tree", ["z"] = 0, ["meta"] = {["inventory"] = {}, ["fields"] = {}}}, {["y"] = 3, ["x"] = 6, ["name"] = "default:wood", ["z"] = 1, ["meta"] = {["inventory"] = {}, ["fields"] = {}}}, {["y"] = 3, ["x"] = 6, ["name"] = "default:wood", ["z"] = 2, ["meta"] = {["inventory"] = {}, ["fields"] = {}}}, {["y"] = 3, ["x"] = 6, ["name"] = "default:wood", ["z"] = 3, ["meta"] = {["inventory"] = {}, ["fields"] = {}}}, {["y"] = 3, ["x"] = 6, ["name"] = "default:tree", ["z"] = 4, ["meta"] = {["inventory"] = {}, ["fields"] = {}}}, {["y"] = 4, ["x"] = 6, ["name"] = "stairs:slab_junglewood", ["z"] = 0, ["meta"] = {["inventory"] = {}, ["fields"] = {}}, ["param1"] = 126}, {["y"] = 4, ["x"] = 6, ["name"] = "stairs:slab_junglewood", ["z"] = 1, ["meta"] = {["inventory"] = {}, ["fields"] = {}}, ["param1"] = 142}, {["y"] = 4, ["x"] = 6, ["name"] = "stairs:slab_junglewood", ["z"] = 2, ["meta"] = {["inventory"] = {}, ["fields"] = {}}, ["param1"] = 126}, {["y"] = 4, ["x"] = 6, ["name"] = "stairs:slab_junglewood", ["z"] = 3, ["meta"] = {["inventory"] = {}, ["fields"] = {}}, ["param1"] = 110}, {["y"] = 4, ["x"] = 6, ["name"] = "stairs:slab_junglewood", ["z"] = 4, ["meta"] = {["inventory"] = {}, ["fields"] = {}}, ["param1"] = 94}}