return {{["y"] = 0, ["x"] = 0, ["name"] = "default:wood", ["z"] = 0, ["meta"] = {["inventory"] = {}, ["fields"] = {}}}, {["y"] = 0, ["x"] = 0, ["name"] = "default:wood", ["z"] = 1, ["meta"] = {["inventory"] = {}, ["fields"] = {}}}, {["y"] = 0, ["x"] = 0, ["name"] = "doors:door_wood_a", ["z"] = 2, ["meta"] = {["inventory"] = {}, ["fields"] = {["state"] = "0"}}, ["param2"] = 1, ["param1"] = 158}, {["y"] = 0, ["x"] = 0, ["name"] = "default:wood", ["z"] = 3, ["meta"] = {["inventory"] = {}, ["fields"] = {}}}, {["y"] = 0, ["x"] = 0, ["name"] = "default:wood", ["z"] = 4, ["meta"] = {["inventory"] = {}, ["fields"] = {}}}, {["y"] = 1, ["x"] = 0, ["name"] = "default:wood", ["z"] = 0, ["meta"] = {["inventory"] = {}, ["fields"] = {}}}, {["y"] = 1, ["x"] = 0, ["name"] = "default:wood", ["z"] = 1, ["meta"] = {["inventory"] = {}, ["fields"] = {}}}, {["y"] = 1, ["x"] = 0, ["name"] = "doors:hidden", ["z"] = 2, ["meta"] = {["inventory"] = {}, ["fields"] = {}}, ["param2"] = 1, ["param1"] = 174}, {["y"] = 1, ["x"] = 0, ["name"] = "default:wood", ["z"] = 3, ["meta"] = {["inventory"] = {}, ["fields"] = {}}}, {["y"] = 1, ["x"] = 0, ["name"] = "default:wood", ["z"] = 4, ["meta"] = {["inventory"] = {}, ["fields"] = {}}}, {["y"] = 2, ["x"] = 0, ["name"] = "default:wood", ["z"] = 0, ["meta"] = {["inventory"] = {}, ["fields"] = {}}}, {["y"] = 2, ["x"] = 0, ["name"] = "default:wood", ["z"] = 1, ["meta"] = {["inventory"] = {}, ["fields"] = {}}}, {["y"] = 2, ["x"] = 0, ["name"] = "default:wood", ["z"] = 2, ["meta"] = {["inventory"] = {}, ["fields"] = {}}}, {["y"] = 2, ["x"] = 0, ["name"] = "default:wood", ["z"] = 3, ["meta"] = {["inventory"] = {}, ["fields"] = {}}}, {["y"] = 2, ["x"] = 0, ["name"] = "default:wood", ["z"] = 4, ["meta"] = {["inventory"] = {}, ["fields"] = {}}}, {["y"] = 0, ["x"] = 1, ["name"] = "default:wood", ["z"] = 0, ["meta"] = {["inventory"] = {}, ["fields"] = {}}}, {["y"] = 0, ["x"] = 1, ["name"] = "beds:bed_bottom", ["z"] = 1, ["meta"] = {["inventory"] = {}, ["fields"] = {}}, ["param2"] = 1, ["param1"] = 156}, {["y"] = 0, ["x"] = 1, ["name"] = "default:chest", ["z"] = 3, ["meta"] = {["inventory"] = {["main"] = {"", "", "", "", "", "", "", "", "", "", "", "", "", "", "", "", "", "", "", "", "", "", "", "", "", "", "", "", "", "", "", ""}}, ["fields"] = {["infotext"] = "Chest"}}, ["param1"] = 156}, {["y"] = 0, ["x"] = 1, ["name"] = "default:wood", ["z"] = 4, ["meta"] = {["inventory"] = {}, ["fields"] = {}}}, {["y"] = 1, ["x"] = 1, ["name"] = "default:wood", ["z"] = 0, ["meta"] = {["inventory"] = {}, ["fields"] = {}}}, {["y"] = 1, ["x"] = 1, ["name"] = "default:wood", ["z"] = 4, ["meta"] = {["inventory"] = {}, ["fields"] = {}}}, {["y"] = 2, ["x"] = 1, ["name"] = "default:wood", ["z"] = 0, ["meta"] = {["inventory"] = {}, ["fields"] = {}}}, {["y"] = 2, ["x"] = 1, ["name"] = "default:torch_wall", ["z"] = 2, ["meta"] = {["inventory"] = {}, ["fields"] = {}}, ["param2"] = 3, ["param1"] = 204}, {["y"] = 2, ["x"] = 1, ["name"] = "default:wood", ["z"] = 4, ["meta"] = {["inventory"] = {}, ["fields"] = {}}}, {["y"] = 3, ["x"] = 1, ["name"] = "default:wood", ["z"] = 1, ["meta"] = {["inventory"] = {}, ["fields"] = {}}}, {["y"] = 3, ["x"] = 1, ["name"] = "default:wood", ["z"] = 2, ["meta"] = {["inventory"] = {}, ["fields"] = {}}}, {["y"] = 3, ["x"] = 1, ["name"] = "default:wood", ["z"] = 3, ["meta"] = {["inventory"] = {}, ["fields"] = {}}}, {["y"] = 0, ["x"] = 2, ["name"] = "default:wood", ["z"] = 0, ["meta"] = {["inventory"] = {}, ["fields"] = {}}}, {["y"] = 0, ["x"] = 2, ["name"] = "beds:bed_top", ["z"] = 1, ["meta"] = {["inventory"] = {}, ["fields"] = {}}, ["param2"] = 1, ["param1"] = 139}, {["y"] = 0, ["x"] = 2, ["name"] = "default:chest", ["z"] = 3, ["meta"] = {["inventory"] = {["main"] = {"", "", "", "", "", "", "", "", "", "", "", "", "", "", "", "", "", "", "", "", "", "", "", "", "", "", "", "", "", "", "", ""}}, ["fields"] = {["infotext"] = "Chest"}}, ["param1"] = 139}, {["y"] = 0, ["x"] = 2, ["name"] = "default:wood", ["z"] = 4, ["meta"] = {["inventory"] = {}, ["fields"] = {}}}, {["y"] = 1, ["x"] = 2, ["name"] = "default:wood", ["z"] = 0, ["meta"] = {["inventory"] = {}, ["fields"] = {}}}, {["y"] = 1, ["x"] = 2, ["name"] = "default:wood", ["z"] = 4, ["meta"] = {["inventory"] = {}, ["fields"] = {}}}, {["y"] = 2, ["x"] = 2, ["name"] = "default:wood", ["z"] = 0, ["meta"] = {["inventory"] = {}, ["fields"] = {}}}, {["y"] = 2, ["x"] = 2, ["name"] = "default:wood", ["z"] = 4, ["meta"] = {["inventory"] = {}, ["fields"] = {}}}, {["y"] = 3, ["x"] = 2, ["name"] = "default:wood", ["z"] = 1, ["meta"] = {["inventory"] = {}, ["fields"] = {}}}, {["y"] = 3, ["x"] = 2, ["name"] = "default:wood", ["z"] = 2, ["meta"] = {["inventory"] = {}, ["fields"] = {}}}, {["y"] = 3, ["x"] = 2, ["name"] = "default:wood", ["z"] = 3, ["meta"] = {["inventory"] = {}, ["fields"] = {}}}, {["y"] = 0, ["x"] = 3, ["name"] = "default:wood", ["z"] = 0, ["meta"] = {["inventory"] = {}, ["fields"] = {}}}, {["y"] = 0, ["x"] = 3, ["name"] = "default:wood", ["z"] = 1, ["meta"] = {["inventory"] = {}, ["fields"] = {}}}, {["y"] = 0, ["x"] = 3, ["name"] = "default:wood", ["z"] = 2, ["meta"] = {["inventory"] = {}, ["fields"] = {}}}, {["y"] = 0, ["x"] = 3, ["name"] = "default:wood", ["z"] = 3, ["meta"] = {["inventory"] = {}, ["fields"] = {}}}, {["y"] = 0, ["x"] = 3, ["name"] = "default:wood", ["z"] = 4, ["meta"] = {["inventory"] = {}, ["fields"] = {}}}, {["y"] = 1, ["x"] = 3, ["name"] = "default:wood", ["z"] = 0, ["meta"] = {["inventory"] = {}, ["fields"] = {}}}, {["y"] = 1, ["x"] = 3, ["name"] = "default:wood", ["z"] = 1, ["meta"] = {["inventory"] = {}, ["fields"] = {}}}, {["y"] = 1, ["x"] = 3, ["name"] = "default:wood", ["z"] = 2, ["meta"] = {["inventory"] = {}, ["fields"] = {}}}, {["y"] = 1, ["x"] = 3, ["name"] = "default:wood", ["z"] = 3, ["meta"] = {["inventory"] = {}, ["fields"] = {}}}, {["y"] = 1, ["x"] = 3, ["name"] = "default:wood", ["z"] = 4, ["meta"] = {["inventory"] = {}, ["fields"] = {}}}, {["y"] = 2, ["x"] = 3, ["name"] = "default:wood", ["z"] = 0, ["meta"] = {["inventory"] = {}, ["fields"] = {}}}, {["y"] = 2, ["x"] = 3, ["name"] = "default:wood", ["z"] = 1, ["meta"] = {["inventory"] = {}, ["fields"] = {}}}, {["y"] = 2, ["x"] = 3, ["name"] = "default:wood", ["z"] = 2, ["meta"] = {["inventory"] = {}, ["fields"] = {}}}, {["y"] = 2, ["x"] = 3, ["name"] = "default:wood", ["z"] = 3, ["meta"] = {["inventory"] = {}, ["fields"] = {}}}, {["y"] = 2, ["x"] = 3, ["name"] = "default:wood", ["z"] = 4, ["meta"] = {["inventory"] = {}, ["fields"] = {}}}}